Traceback (most recent call last):
  File "/home/danosis/anaconda3/lib/python3.9/site-packages/jupyter_cache/executors/utils.py", line 58, in single_nb_execution
    executenb(
  File "/home/danosis/anaconda3/lib/python3.9/site-packages/nbclient/client.py", line 1204, in execute
    return NotebookClient(nb=nb, resources=resources, km=km, **kwargs).execute()
  File "/home/danosis/anaconda3/lib/python3.9/site-packages/nbclient/util.py", line 84, in wrapped
    return just_run(coro(*args, **kwargs))
  File "/home/danosis/anaconda3/lib/python3.9/site-packages/nbclient/util.py", line 62, in just_run
    return loop.run_until_complete(coro)
  File "/home/danosis/anaconda3/lib/python3.9/asyncio/base_events.py", line 642, in run_until_complete
    return future.result()
  File "/home/danosis/anaconda3/lib/python3.9/site-packages/nbclient/client.py", line 663, in async_execute
    await self.async_execute_cell(
  File "/home/danosis/anaconda3/lib/python3.9/site-packages/nbclient/client.py", line 965, in async_execute_cell
    await self._check_raise_for_error(cell, cell_index, exec_reply)
  File "/home/danosis/anaconda3/lib/python3.9/site-packages/nbclient/client.py", line 862, in _check_raise_for_error
    raise CellExecutionError.from_cell_and_msg(cell, exec_reply_content)
nbclient.exceptions.CellExecutionError: An error occurred while executing the following cell:
------------------
train = get_data_train(train_folder)
test = get_data_train(test_folder)
------------------

[0;31m---------------------------------------------------------------------------[0m
[0;31mFileNotFoundError[0m                         Traceback (most recent call last)
[0;32m/tmp/ipykernel_67167/2470347292.py[0m in [0;36m<module>[0;34m[0m
[0;32m----> 1[0;31m [0mtrain[0m [0;34m=[0m [0mget_data_train[0m[0;34m([0m[0mtrain_folder[0m[0;34m)[0m[0;34m[0m[0;34m[0m[0m
[0m[1;32m      2[0m [0mtest[0m [0;34m=[0m [0mget_data_train[0m[0;34m([0m[0mtest_folder[0m[0;34m)[0m[0;34m[0m[0;34m[0m[0m

[0;32m/tmp/ipykernel_67167/881923197.py[0m in [0;36mget_data_train[0;34m(data_dir)[0m
[1;32m      9[0m         [0mpath[0m [0;34m=[0m [0mos[0m[0;34m.[0m[0mpath[0m[0;34m.[0m[0mjoin[0m[0;34m([0m[0mdata_dir[0m[0;34m,[0m [0mlabel[0m[0;34m)[0m[0;34m[0m[0;34m[0m[0m
[1;32m     10[0m         [0mclass_num[0m [0;34m=[0m [0mlabels[0m[0;34m.[0m[0mindex[0m[0;34m([0m[0mlabel[0m[0;34m)[0m[0;34m[0m[0;34m[0m[0m
[0;32m---> 11[0;31m         [0;32mfor[0m [0mimg[0m [0;32min[0m [0mos[0m[0;34m.[0m[0mlistdir[0m[0;34m([0m[0mpath[0m[0;34m)[0m[0;34m:[0m[0;34m[0m[0;34m[0m[0m
[0m[1;32m     12[0m             [0;32mtry[0m[0;34m:[0m[0;34m[0m[0;34m[0m[0m
[1;32m     13[0m                 [0mimg_array[0m [0;34m=[0m [0mcv2[0m[0;34m.[0m[0mimread[0m[0;34m([0m[0mos[0m[0;34m.[0m[0mpath[0m[0;34m.[0m[0mjoin[0m[0;34m([0m[0mpath[0m[0;34m,[0m [0mimg[0m[0;34m)[0m[0;34m,[0m [0mcv2[0m[0;34m.[0m[0mIMREAD_GRAYSCALE[0m[0;34m)[0m[0;34m[0m[0;34m[0m[0m

[0;31mFileNotFoundError[0m: [Errno 2] No such file or directory: 'chest_xray/train/NORMAL'
FileNotFoundError: [Errno 2] No such file or directory: 'chest_xray/train/NORMAL'

